Workbook

Sheet README
A1: AI unit economics planning tool (v0.1, thin workbook)
A2: Built 2026-09-20. Status: first build from the approved spec. FICTIONAL WORKED EXAMPLE: every organization input is an assumption (grade D). Only dated primary prices are grade A.
A3: What it is
A4: A planning workbook an enterprise runs before it builds AI. Enter the org shape, teams, users and usage; it returns cost by layer, by team and for the organization, plus payback, sensitivity and the one number that would kill the case. Formulas are visible and there are no macros.
A5: How to use it (about 30 minutes)
A6: 1. Org: set the organization, horizon (up to 60 months), scenario, value case, org shape and allocation rule.
A7: 2. Teams: replace the five fictional teams (one team per business unit in v0.1; Teams 1 and 5 are the same kind of seat-based assistant at two calibrations, on purpose). Blue text on pale yellow is an input.
A8: 3. Params: review every starter value (grade D). Replace any you can with the enterprise's own value; the Summary shows how much cost still rests on starters.
A9: 4. PriceBook: check every price against the provider's page and follow the refresh procedure at the bottom of that sheet.
A10: 5. Read Summary, then Sensitivity (kill number), Scenarios, Allocation (cost-center table) and Tests (all twelve should pass).
A11: Colours
A12: Blue text on pale yellow = input. Black = formula. Green = link to another sheet.
... A24: Evidence base: evidence/. Design: research/ and spec/. Build scripts and the independent reference model used to verify this workbook: model/build/.

Sheet Summary
A1: AI unit economics: summary
A2: FICTIONAL WORKED EXAMPLE. Every input is an assumption (grade D) except dated primary prices (grade A). Not a forecast for any real organization.
A4: Settings (change them on the Org sheet)
A5: Organization | B5: =Org!$B$4 -> Northwind Example Co (fictional)
A6: Scenario | B6: =Org!$B$6 -> Base
A7: Value case | B7: =Org!$B$7 -> Base
A8: Org shape | B8: =Org!$B$8 -> Hub-and-spoke
A9: Allocation rule | B9: =Org!$B$9 -> Usage-proportional
A10: Horizon (months) | B10: =Org!$B$5 -> 36
A11: =IF(Org!$B$6="High-cost","Stress case: every parameter is at its high value at once. Not a likely outcome.","")
A13: Headline (enterprise, over the horizon)
A14: Total cost | B14: =Results!$J$57 -> 18344688
A15: Benefit | B15: =Results!$J$54 -> 26033657
A16: Net value | B16: =Results!$J$58 -> 7688968.4
A17: Payback month | B17: =Results!$J$59 -> 12
A18: Cost per outcome | B18: =Results!$J$60 -> 1.5099503
A19: Benefit per outcome | B19: =Results!$J$62 -> 2.1428289
A20: Cost per active user per month | B20: =Results!$J$61 -> 140.26022
A21: Run-rate at the last horizon month (per month) | B21: =Results!$J$63 -> 458413.6
A23: Cost by layer | B23: =Teams!C$4 -> Corporate knowledge assistant (conservative calibration) | C23: =Teams!D$4 -> Engineering assistant | D23: =Teams!E$4 -> Customer service agent | E23: =Teams!F$4 -> Regulated document review | F23: =Teams!G$4 -> Sales assistant (published-range calibration) | G23: Hub (after shape) | H23: Enterprise
A24: L1 Data readiness | B24: =Results!D36 -> 47681.6 | C24: =Results!E36 -> 39150.56 | D24: =Results!F36 -> 42980 | E24: =Results!G36 -> 141125.63 | F24: =Results!H36 -> 31760.096 | G24: =Results!I36*Results!$D$3 -> 58240 | H24: =Results!J36 -> 360937.89
A25: L2 Setup and infrastructure | B25: =Results!D37 -> 48000 | C25: =Results!E37 -> 48000 | D25: =Results!F37 -> 48000 | E25: =Results!G37 -> 48000 | F25: =Results!H37 -> 48000 | G25: =Results!I37*Results!$D$3 -> 297600 | H25: =Results!J37 -> 537600
A26: L3 Inference and usage | B26: =Results!D38 -> 3024000 | C26: =Results!E38 -> 1043787.8 | D26: =Results!F38 -> 1287000 | E26: =Results!G38 -> 50143.182 | F26: =Results!H38 -> 2016000 | G26: =Results!I38*Results!$D$3 -> 0 | H26: =Results!J38 -> 7420931
A27: L4 Run and maintenance | B27: =Results!D39 -> 263000 | C27: =Results!E39 -> 164480 | D27: =Results!F39 -> 142115 | E27: =Results!G39 -> 141920 | F27: =Results!H39 -> 222800 | G27: =Results!I39*Results!$D$3 -> 3179735.7 | H27: =Results!J39 -> 4114050.7
A28: L5 People and change | B28: =Results!D40 -> 1408120 | C28: =Results!E40 -> 2233862.4 | D28: =Results!F40 -> 330377 | E28: =Results!G40 -> 1000062.4 | F28: =Results!H40 -> 938746.7 | G28: =Results!I40*Results!$D$3 -> 0 | H28: =Results!J40 -> 5911168.5
A30: Teams (cost includes the allocated hub share) | B30: Buying model | C30: Outcomes | D30: Total cost | E30: Cost per outcome | F30: Cost per active user per month | G30: Benefit | H30: Net value | I30: Payback month
A31: =Teams!$C$4 -> Corporate knowledge assistant (conservative calibration) | B31: =Results!D50 -> Seat | C31: =Results!D52 -> 3618000 | D31: =Results!D57 -> 5843686.8 | E31: =Results!D60 -> 1.6151705 | F31: =Results!D61 -> 96.91023 | G31: =Results!D54 -> 2544720.3 | H31: =Results!D58 -> -3298966.5 | I31: =Results!D59 -> None
A32: =Teams!$D$4 -> Engineering assistant | B32: =Results!E50 -> Seat + usage | C32: =Results!E52 -> 4416000 | D32: =Results!E57 -> 4814394.4 | E32: =Results!E60 -> 1.0902161 | F32: =Results!E61 -> 436.08645 | G32: =Results!E54 -> 13763200 | H32: =Results!E58 -> 8948805.6 | I32: =Results!E59 -> 3
A33: =Teams!$E$4 -> Customer service agent | B33: =Results!F50 -> Per-unit | C33: =Results!F52 -> 1300000 | D33: =Results!F57 -> 2228789 | E33: =Results!F60 -> 1.714453 | F33: =Results!F61 -> n/a | G33: =Results!F54 -> 2590672.5 | H33: =Results!F58 -> 361883.54 | I33: =Results!F59 -> 14
A34: =Teams!$F$4 -> Regulated document review | B34: =Results!G50 -> Per-unit | C34: =Results!G52 -> 403200 | D34: =Results!G57 -> 1498587.7 | E34: =Results!G60 -> 3.7167353 | F34: =Results!G61 -> 446.00824 | G34: =Results!G54 -> 1197383 | H34: =Results!G58 -> -301204.63 | I34: =Results!G59 -> None
A35: =Teams!$G$4 -> Sales assistant (published-range calibration) | B35: =Results!H50 -> Seat | C35: =Results!H52 -> 2412000 | D35: =Results!H57 -> 3959230.3 | E35: =Results!H60 -> 1.6414719 | F35: =Results!H61 -> 98.488315 | G35: =Results!H54 -> 5937680.7 | H35: =Results!H58 -> 1978450.4 | I35: =Results!H59 -> 13
A37: How much of the cost rests on what evidence | B37: Cost | C37: Share
A38: Dated primary prices (A) | B38: =Results!D43 -> 7494384.6 | C38: =Results!E43 -> 0.40853159
A39: Ranges with a warning (B*/C) | B39: =Results!D44 -> 4619616.5 | C39: =Results!E44 -> 0.25182312
A40: Starter values (D) | B40: =Results!D45 -> 6230687 | C40: =Results!E45 -> 0.33964529
A41: Enterprise-entered, off until entered | B41: =Results!D46 -> 0 | C41: =Results!E46 -> 0
A43: Cost lines that are OFF (they understate cost until entered)
A44: =Lines!$A$17&" "&Lines!$B$17&": "&Lines!$H$17 -> CL-14 Environments and base cloud infrastructure: OFF
A45: =Lines!$A$18&" "&Lines!$B$18&": "&Lines!$H$18 -> CL-15 Committed capacity (provisioned cloud or self-hosted GPUs): OFF
A46: =Lines!$A$34&" "&Lines!$B$34&": "&Lines!$H$34 -> CL-31 Compliance audit and governance: OFF
...

Sheet Org
A1: Organization inputs
A2: Blue text on pale yellow = input. Everything here is a fictional assumption (grade D) unless stated.
A3: Field | B3: Value | C3: Unit / options | D3: Label | E3: Source | F3: Grade
A4: Organization name | B4: Northwind Example Co (fictional) | C4: text | D4: assumed | E4: Fictional worked example (Claude, 2026-09-20) | F4: D
A5: Horizon | B5: 36 | C5: months (max 60) | D5: assumed | E5: Project owner's choice, 2026-09-20 | F5: D
A6: Scenario shown on Summary | B6: Base | C6: Low-cost / Base / High-cost (High-cost is a stress case: every parameter at its high value at once) | D6: assumed | E6: User choice | F6: D
A7: Value case (realisation share) | B7: Base | C7: Low / Base / High | D7: assumed | E7: User choice | F7: D
A8: Org shape | B8: Hub-and-spoke | C8: Centralized / Federated / Hub-and-spoke | D8: assumed | E8: User choice; definitions in research/enterprise-structure.md | F8: D
A9: Allocation rule | B9: Usage-proportional | C9: Usage-proportional / Headcount proxy / Even split / Central budget | D9: assumed | E9: Default per shape (D), research/enterprise-structure.md | F9: D
A10: Person-day rate | B10: 800 | C10: USD per person-day | D10: assumed | E10: spec/starter-values.md (Claude, 2026-09-20); cross-check BLS LAB-02 (S41, S42) | F10: D
A11: Hours per person-day | B11: 8 | C11: hours | D11: assumed | E11: spec/starter-values.md (Claude, 2026-09-20) | F11: D
A12: Working days per year | B12: 220 | C12: days | D12: assumed | E12: spec/starter-values.md (Claude, 2026-09-20) | F12: D
A13: Monitoring units per outcome | B13: 5 | C13: units | D13: assumed | E13: Fictional worked example (Claude, 2026-09-20) | F13: D
A15: Derived
A16: Scenario index (1 low-cost, 2 base, 3 high-cost) | B16: =MATCH($B$6,{"Low-cost","Base","High-cost"},0) -> 2
A17: Value-case index (1 low, 2 base, 3 high) | B17: =MATCH($B$7,{"Low","Base","High"},0) -> 2
A18: Number of active teams | B18: =SUM(Teams!C5:G5) -> 5
A19: Number of business units (v0.1: one team per unit) | B19: =B18 -> 5

Sheet Teams
A1: Teams (worked example: fictional)
A2: One team per business unit in v0.1. Blue text on pale yellow = input. IDs refer to the PriceBook.
A3: Field | B3: Unit / options | C3: Team 1 | D3: Team 2 | E3: Team 3 | F3: Team 4 | G3: Team 5 | H3: Label | I3: Source | J3: Grade
A4: Team name | B4: text | C4: Corporate knowledge assistant (conservative calibration) | D4: Engineering assistant | E4: Customer service agent | F4: Regulated document review | G4: Sales assistant (published-range calibration) | H4: assumed | I4: Fictional worked example (Claude, 2026-09-20); prices come from PriceBook (A) | J4: D
A5: Team is active (1 = counted, 0 = ignored) | B5: 1 / 0 | C5: 1 | D5: 1 | E5: 1 | F5: 1 | G5: 1 | H5: assumed | I5: Fictional worked example (Claude, 2026-09-20); prices come from PriceBook (A) | J5: D
A6: Archetype | B6: text | C6: A1 Knowledge-worker assistant | D6: A2 Developer productivity and agents | E6: A3 High-volume service operations | F6: A4 Regulated document and decision work | G6: A1 Knowledge-worker assistant | H6: assumed | I6: Fictional worked example (Claude, 2026-09-20); prices come from PriceBook (A) | J6: D
A7: Business unit and cost center | B7: text | C7: Corporate functions | D7: Engineering | E7: Customer operations | F7: Risk and legal | G7: Sales and marketing | H7: assumed | I7: Fictional worked example (Claude, 2026-09-20); prices come from PriceBook (A) | J7: D
A8: Buying model | B8: Seat / Seat + usage / Per-unit / Committed capacity | C8: Seat | D8: Seat + usage | E8: Per-unit | F8: Per-unit | G8: Seat | H8: assumed | I8: Fictional worked example (Claude, 2026-09-20); prices come from PriceBook (A) | J8: D
A9: Seat price (price book ID) | B9: ID | C9: SEAT_TEAM_STD | D9: SEAT_ENT | E9: SEAT_TEAM_STD | F9: SEAT_TEAM_STD | G9: SEAT_TEAM_STD | H9: assumed | I9: Fictional worked example (Claude, 2026-09-20); prices come from PriceBook (A) | J9: D
A10: Premium seat price (price book ID) | B10: ID | C10: SEAT_TEAM_PREM | D10: SEAT_TEAM_PREM | E10: SEAT_TEAM_PREM | F10: SEAT_TEAM_PREM | G10: SEAT_TEAM_PREM | H10: assumed | I10: Fictional worked example (Claude, 2026-09-20); prices come from PriceBook (A) | J10: D
A11: Share of licensed users on premium seats | B11: share | C11: 0.1 | D11: 0 | E11: 0 | F11: 0 | G11: 0.1 | H11: assumed | I11: Fictional worked example (Claude, 2026-09-20); prices come from PriceBook (A) | J11: D
A12: Usage included per seat per month (hybrid) | B12: USD | C12: 0 | D12: 0 | E12: 0 | F12: 0 | G12: 0 | H12: assumed | I12: Fictional worked example (Claude, 2026-09-20); prices come from PriceBook (A) | J12: D
A13: Top segment share of active users | B13: share | C13: 0.1 | D13: 0.1 | E13: 0.1 | F13: 0.1 | G13: 0.1 | H13: assumed | I13: Fictional worked example (Claude, 2026-09-20); prices come from PriceBook (A) | J13: D
A14: Top segment intensity vs the rest | B14: multiple | C14: 5 | D14: 5 | E14: 5 | F14: 5 | G14: 5 | H14: assumed | I14: Fictional worked example (Claude, 2026-09-20); prices come from PriceBook (A) | J14: D
A15: Vendor per-outcome price (price book ID, or none) | B15: ID | E15: OUT_FIN | H15: assumed | I15: Fictional worked example (Claude, 2026-09-20); prices come from PriceBook (A) | J15: D
A16: Committed capacity cost | B16: USD per month | C16: 0 | D16: 0 | E16: 0 | F16: 0 | G16: 0 | H16: assumed | I16: Fictional worked example (Claude, 2026-09-20); prices come from PriceBook (A) | J16: D
A17: Committed capacity outcomes per month | B17: outcomes | C17: 0 | D17: 0 | E17: 0 | F17: 0 | G17: 0 | H17: assumed | I17: Fictional worked example (Claude, 2026-09-20); prices come from PriceBook (A) | J17: D
A18: Licensed users | B18: users | C18: 3000 | D18: 400 | E18: 60 | F18: 150 | G18: 2000 | H18: assumed | I18: Fictional worked example (Claude, 2026-09-20); prices come from PriceBook (A) | J18: D
A19: Active share of licensed users at plateau | B19: share | C19: 0.6 | D19: 0.8 | E19: 0.85 | F19: 0.7 | G19: 0.6 | H19: assumed | I19: Fictional worked example (Claude, 2026-09-20); prices come from PriceBook (A) | J19: D
A20: Launch month | B20: month | C20: 1 | D20: 1 | E20: 2 | F20: 3 | G20: 1 | H20: assumed | I20: Fictional worked example (Claude, 2026-09-20); prices come from PriceBook (A) | J20: D
A21: Months to plateau | B21: months | C21: 6 | D21: 4 | E21: 6 | F21: 5 | G21: 6 | H21: assumed | I21: Fictional worked example (Claude, 2026-09-20); prices come from PriceBook (A) | J21: D
A22: Ramp curve | B22: Linear / S | C22: S | D22: Linear | E22: S | F22: S | G22: S | H22: assumed | I22: Fictional worked example (Claude, 2026-09-20); prices come from PriceBook (A) | J22: D
A23: Outcome basis | B23: per user / direct volume | C23: per user | D23: per user | E23: direct volume | F23: per user | G23: per user | H23: assumed | I23: Fictional worked example (Claude, 2026-09-20); prices come from PriceBook (A) | J23: D
A24: Outcomes per active user per month | B24: outcomes | C24: 60 | D24: 400 | E24: 0 | F24: 120 | G24: 60 | H24: assumed | I24: Fictional worked example (Claude, 2026-09-20); prices come from PriceBook (A) | J24: D
A25: Direct volume at plateau | B25: outcomes per month | C25: 0 | D25: 0 | E25: 40000 | F25: 0 | G25: 0 | H25: assumed | I25: Fictional worked example (Claude, 2026-09-20); prices come from PriceBook (A) | J25: D
A26: Main model (price book ID) | B26: ID | C26: M_SONNET5 | D26: M_SONNET5 | E26: M_SONNET5 | F26: M_OPUS5 | G26: M_SONNET5 | H26: assumed | I26: Fictional worked example (Claude, 2026-09-20); prices come from PriceBook (A) | J26: D
A27: Cheaper model (price book ID) | B27: ID | C27: M_HAIKU45 | D27: M_HAIKU45 | E27: M_HAIKU45 | F27: M_SONNET5 | G27: M_HAIKU45 | H27: assumed | I27: Fictional worked example (Claude, 2026-09-20); prices come from PriceBook (A) | J27: D
A28: Share routed to cheaper model | B28: share | C28: 0 | D28: 0 | E28: 0 | F28: 0.5 | G28: 0 | H28: assumed | I28: Fictional worked example (Claude, 2026-09-20); prices come from PriceBook (A) | J28: D
A29: Input tokens per outcome | B29: tokens | C29: 2000 | D29: 8000 | E29: 0 | F29: 30000 | G29: 2000 | H29: assumed | I29: Fictional worked example (Claude, 2026-09-20); prices come from PriceBook (A) | J29: D
A30: Output tokens per outcome | B30: tokens | C30: 500 | D30: 2000 | E30: 0 | F30: 1500 | G30: 500 | H30: assumed | I30: Fictional worked example (Claude, 2026-09-20); prices come from PriceBook (A) | J30: D
A31: Context-management reduction | B31: share | C31: 0 | D31: 0.1 | E31: 0 | F31: 0 | G31: 0 | H31: assumed | I31: Fictional worked example (Claude, 2026-09-20); prices come from PriceBook (A) | J31: D
A32: Cached share of input | B32: share | C32: 0.3 | D32: 0.6 | E32: 0 | F32: 0.3 | G32: 0.3 | H32: assumed | I32: Fictional worked example (Claude, 2026-09-20); prices come from PriceBook (A) | J32: D
A33: Cache-write share of input | B33: share | C33: 0.05 | D33: 0.05 | E33: 0 | F33: 0.05 | G33: 0.05 | H33: assumed | I33: Fictional worked example (Claude, 2026-09-20); prices come from PriceBook (A) | J33: D
A34: Asynchronous (batch) share | B34: share | C34: 0 | D34: 0 | E34: 0 | F34: 0.4 | G34: 0 | H34: assumed | I34: Fictional worked example (Claude, 2026-09-20); prices come from PriceBook (A) | J34: D
A35: Residency multiplier | B35: multiplier | C35: 1 | D35: 1 | E35: 1 | F35: 1.1 | G35: 1 | H35: assumed | I35: Fictional worked example (Claude, 2026-09-20); prices come from PriceBook (A) | J35: D
A36: Agentic workflow | B36: Yes / No | C36: No | D36: Yes | E36: No | F36: No | G36: No | H36: assumed | I36: Fictional worked example (Claude, 2026-09-20); prices come from PriceBook (A) | J36: D
A37: Tool calls per outcome | B37: calls | C37: 0 | D37: 0 | E37: 0 | F37: 0 | G37: 0 | H37: assumed | I37: Fictional worked example (Claude, 2026-09-20); prices come from PriceBook (A) | J37: D
A38: Tool price (price book ID) | B38: ID | C38: U_TOOL_SEARCH | D38: U_TOOL_SEARCH | E38: U_TOOL_SEARCH | F38: U_TOOL_SEARCH | G38: U_TOOL_SEARCH | H38: assumed | I38: Fictional worked example (Claude, 2026-09-20); prices come from PriceBook (A) | J38: D
A39: Guardrail text units per outcome | B39: units | C39: 0 | D39: 0 | E39: 0 | F39: 126 | G39: 0 | H39: assumed | I39: Fictional worked example (Claude, 2026-09-20); prices come from PriceBook (A) | J39: D
A40: Guardrail price (price book ID) | B40: ID | C40: U_GUARD_CF | D40: U_GUARD_CF | E40: U_GUARD_CF | F40: U_GUARD_CF | G40: U_GUARD_CF | H40: assumed | I40: Fictional worked example (Claude, 2026-09-20); prices come from PriceBook (A) | J40: D
...

Sheet Params
A1: Scenario parameters (starter values)
A2: Grade D unless stated. Low, Base and High are the low-cost, base and high-cost values. Source: spec/starter-values.md. Every value is editable.
A3: Key | B3: Parameter | C3: Unit | D3: Low-cost | E3: Base | F3: High-cost (stress) | G3: Taxonomy line | H3: How it was built | I3: Label | J3: Source | K3: Grade
A4: src_pd | B4: Assess one source system | C4: person-days | D4: 1 | E4: 3 | F4: 8 | G4: CL-01 | H4: Owner interview, access check, sample review | I4: assumed | J4: spec/starter-values.md (Claude, 2026-09-20) | K4: D
A5: clean_pd | B5: Clean and label 100,000 documents | C5: person-days | D5: 5 | E5: 20 | F5: 60 | G5: CL-02 | H5: Pipeline plus sampled review; range wide because published shares conflict (CST-07) | I5: assumed | J5: spec/starter-values.md (Claude, 2026-09-20) | K5: D
A6: conn_pd | B6: Build one connector | C6: person-days | D6: 5 | E6: 10 | F6: 25 | G6: CL-03 | H6: Standard vs custom source | I6: assumed | J6: spec/starter-values.md (Claude, 2026-09-20) | K6: D
A7: conn_up | B7: Connector upkeep per year | C7: share of build | D7: 0.1 | E7: 0.15 | F7: 0.25 | G7: CL-03 | H7: Yearly upkeep share | I7: assumed | J7: spec/starter-values.md (Claude, 2026-09-20) | K7: D
A8: perm_pd | B8: Map permissions for one source | C8: person-days | D8: 2 | E8: 4 | F8: 10 | G8: CL-04 | H8: Map groups once, revise on org change | I8: assumed | J8: spec/starter-values.md (Claude, 2026-09-20) | K8: D
A9: perm_up | B9: Permission upkeep per year | C9: share of build | D9: 0.05 | E9: 0.1 | F9: 0.2 | G9: CL-04 | H9: Org change rate | I9: assumed | J9: spec/starter-values.md (Claude, 2026-09-20) | K9: D
A10: change_rate | B10: Share of documents changing per month | C10: share | D10: 0.01 | E10: 0.03 | F10: 0.1 | G10: CL-08 | H10: Slow policy content vs fast tickets | I10: assumed | J10: spec/starter-values.md (Claude, 2026-09-20) | K10: D
A11: plat_pd | B11: Platform or gateway, one-time | C11: person-days | D11: 60 | E11: 120 | F11: 300 | G11: CL-09 | H11: Configure or build gateway with logging and access control; base x rate = $96,000 vs ENV-01 (B*, 2024) | I11: assumed | J11: spec/starter-values.md (Claude, 2026-09-20) | K11: D
A12: plat_run | B12: Platform run per year | C12: share of one-time | D12: 0.1 | E12: 0.2 | F12: 0.3 | G12: CL-09 | H12: Yearly run share | I12: assumed | J12: spec/starter-values.md (Claude, 2026-09-20) | K12: D
A13: int_pd | B13: Integrate one use case | C13: person-days | D13: 15 | E13: 40 | F13: 120 | G13: CL-10 | H13: Connect one workflow and its systems | I13: assumed | J13: spec/starter-values.md (Claude, 2026-09-20) | K13: D
A14: rev_uc_pd | B14: Security, privacy, legal review per use case | C14: person-days | D14: 5 | E14: 10 | F14: 30 | G14: CL-11 | H14: A few days each from three reviewers | I14: assumed | J14: spec/starter-values.md (Claude, 2026-09-20) | K14: D
A15: rev_once_pd | B15: Platform-level review, once | C15: person-days | D15: 15 | E15: 30 | F15: 60 | G15: CL-11 | H15: One-time platform review | I15: assumed | J15: spec/starter-values.md (Claude, 2026-09-20) | K15: D
... A41: realise | B41: Realisation share of self-reported time saved | C41: share | D41: 0.25 | E41: 0.5 | F41: 0.75 | G41: value | H41: No evidence converts self-reported time saved to cash (G5) | I41: assumed | J41: spec/starter-values.md (Claude, 2026-09-20) | K41: D

Sheet PriceBook
A1: Price book (dated primary prices, grade A)
A2: Fetched 2026-09-20 from each provider's own page (see evidence/source-register.md). 'Effective from' is the first date the price was seen. Confirm on the page before use. Model names are as extracted. Refresh: add a new row with a NEW unique ID, keep the old row, never overwrite (adoption/price-book-refresh.md). Dates and status are recorded, not applied in calculations.
A3: ID | B3: Provider | C3: Product | D3: Kind | E3: Price / input | F3: Output | G3: Cache read x | H3: Cache write x | I3: Batch factor | J3: Unit | K3: Effective from | L3: Effective to | M3: Status | N3: Source | O3: Date fetched | P3: Grade | Q3: Label | R3: Included units
A4: M_HAIKU45 | B4: Anthropic | C4: Claude Haiku 4.5 | D4: Model | E4: 1 | F4: 5 | G4: 0.1 | H4: 1.25 | I4: 0.5 | J4: USD per million tokens | K4: 46285 | M4: standard | N4: S09 | O4: 46285 | P4: A | Q4: quoted
A5: M_SONNET5 | B5: Anthropic | C5: Claude Sonnet 5 | D5: Model | E5: 2 | F5: 10 | G5: 0.1 | H5: 1.25 | I5: 0.5 | J5: USD per million tokens | K5: 46285 | M5: standard | N5: S09 | O5: 46285 | P5: A | Q5: quoted
A6: M_OPUS5 | B6: Anthropic | C6: Claude Opus 5 | D6: Model | E6: 5 | F6: 25 | G6: 0.1 | H6: 1.25 | I6: 0.5 | J6: USD per million tokens | K6: 46285 | M6: standard | N6: S09 | O6: 46285 | P6: A | Q6: quoted
A7: M_GPT54MINI | B7: OpenAI | C7: GPT-5.4 Mini (name as extracted) | D7: Model | E7: 0.75 | F7: 4.5 | G7: 0.1 | H7: 1 | I7: 0.5 | J7: USD per million tokens | K7: 46285 | M7: standard | N7: S12 | O7: 46285 | P7: A | Q7: quoted
A8: M_GEM38FLASH | B8: Google | C8: Gemini 3.8 Flash (name as extracted) | D8: Model | E8: 0.75 | F8: 3.75 | G8: 0.1 | H8: 1 | I8: 0.5 | J8: USD per million tokens | K8: 46285 | L8: 46387 | M8: promotional | N8: S11 | O8: 46285 | P8: A | Q8: quoted
A9: SEAT_TEAM_STD | B9: Anthropic | C9: Claude Team standard seat (annual billing) | D9: Seat | E9: 20 | J9: USD per user per month | K9: 46285 | M9: standard | N9: S33 | O9: 46285 | P9: A | Q9: quoted
A10: SEAT_TEAM_PREM | B10: Anthropic | C10: Claude Team premium seat (annual billing) | D10: Seat | E10: 100 | J10: USD per user per month | K10: 46285 | M10: standard | N10: S33 | O10: 46285 | P10: A | Q10: quoted
A11: SEAT_ENT | B11: Anthropic | C11: Claude Enterprise seat (annual); usage billed at API rates | D11: Seat | E11: 20 | J11: USD per user per month | K11: 46285 | M11: standard | N11: S33 | O11: 46285 | P11: A | Q11: quoted
A12: SEAT_M365_BUS | B12: Microsoft | C12: Microsoft 365 Copilot Business (annual, promotional) | D12: Seat | E12: 18 | J12: USD per user per month | K12: 46285 | L12: 46387 | M12: promotional | N12: S08 | O12: 46285 | P12: A | Q12: quoted
A13: SEAT_M365 | B13: Microsoft | C13: Microsoft 365 Copilot (paid yearly) | D13: Seat | E13: 30 | J13: USD per user per month | K13: 46285 | M13: standard | N13: S35 | O13: 46285 | P13: A | Q13: quoted
A14: OUT_FIN | B14: Intercom | C14: Fin AI agent, per outcome (outcome definition in BUY-06) | D14: Outcome | E14: 0.99 | J14: USD per outcome | K14: 46285 | M14: standard | N14: S37 | O14: 46285 | P14: A | Q14: quoted
A15: U_TEXTRACT_TXT | B15: AWS | C15: Textract detect text, first 1M pages | D15: Unit | E15: 0.0015 | J15: USD per page | K15: 46285 | M15: standard | N15: S45 | O15: 46285 | P15: A | Q15: quoted
A16: U_TEXTRACT_TBL | B16: AWS | C16: Textract tables, first 1M pages | D16: Unit | E16: 0.015 | J16: USD per page | K16: 46285 | M16: standard | N16: S45 | O16: 46285 | P16: A | Q16: quoted
A17: U_EMB_3L | B17: OpenAI | C17: text-embedding-3-large | D17: Unit | E17: 0.13 | J17: USD per million tokens | K17: 46285 | M17: standard | N17: S12 | O17: 46285 | P17: A | Q17: quoted
A18: U_PINE_READ | B18: Pinecone | C18: Read units (low end of range) | D18: Unit | E18: 16 | J18: USD per million read units | K18: 46285 | M18: standard | N18: S43 | O18: 46285 | P18: A | Q18: quoted
A19: U_PINE_STORE | B19: Pinecone | C19: Storage, Standard plan | D19: Unit | E19: 0.33 | J19: USD per GB per month | K19: 46285 | M19: standard | N19: S43 | O19: 46285 | P19: A | Q19: quoted
A20: PL_PINE_STD | B20: Pinecone | C20: Standard plan minimum | D20: Plan | E20: 50 | J20: USD per month | K20: 46285 | M20: standard | N20: S43 | O20: 46285 | P20: A | Q20: quoted
A21: U_GUARD_CF | B21: AWS | C21: Bedrock Guardrails content filters | D21: Unit | E21: 0.15 | J21: USD per 1,000 text units | K21: 46285 | M21: standard | N21: S46 | O21: 46285 | P21: A | Q21: quoted
A22: U_TOOL_SEARCH | B22: Anthropic/OpenAI | C22: Web search tool | D22: Unit | E22: 10 | J22: USD per 1,000 calls | K22: 46285 | M22: standard | N22: S09 | O22: 46285 | P22: A | Q22: quoted
A23: PL_LANGFUSE_PRO | B23: Langfuse | C23: Pro plan (100k units included) | D23: Plan | E23: 199 | J23: USD per month | K23: 46285 | M23: standard | N23: S44 | O23: 46285 | P23: A | Q23: quoted | R23: 100000
A24: U_LANGFUSE_OVER | B24: Langfuse | C24: Overage per 100k units | D24: Unit | E24: 8 | J24: USD per 100k units | K24: 46285 | M24: standard | N24: S44 | O24: 46285 | P24: A | Q24: quoted

Sheet Lines
A1: The 35 cost lines (taxonomy index)
A2: Source: research/cost-taxonomy.md. Policy: P dated primary price, R range with warning, E enterprise-entered (starter value unless off).
A3: ID | B3: Line | C3: Layer | D3: Type | E3: Owner (hub-and-spoke) | F3: Policy | G3: Evidence | H3: Status | I3: Where it is computed
A4: CL-01 | B4: Source inventory and assessment | C4: L1 | D4: One-time | E4: H+S | F4: E | G4: none (G1) | H4: ON | I4: Team: one-time assess, clean, connect
A5: CL-02 | B5: Cleaning, deduplication, labelling | C5: L1 | D5: One-time, then refresh | E5: S | F5: E | G5: CST-07 (C), CST-08 | H5: ON | I5: Team: one-time assess, clean, connect
A6: CL-03 | B6: Connectors to source systems | C6: L1 | D6: One-time plus upkeep | E6: H+S | F6: E | G6: none (G1) | H6: ON | I6: Team: one-time row and connector upkeep
A7: CL-04 | B7: Permission and access mapping | C7: L1 | D7: One-time, then on org change | E7: H | F7: E | G7: ORG-03 | H7: ON | I7: Hub: permission mapping and upkeep
A8: CL-05 | B8: Document parsing and OCR | C8: L1 | D8: Variable | E8: S | F8: P | G8: COMP-01 | H8: ON | I8: Team: parsing, embeddings, index row and initial load
A9: CL-06 | B9: Embeddings | C9: L1 | D9: Variable | E9: S | F9: P | G9: COMP-02 | H9: ON | I9: Team: parsing, embeddings, index row and initial load
A10: CL-07 | B10: Index and retrieval infrastructure | C10: L1 | D10: Recurring fixed plus variable | E10: H+S | F10: P | G10: COMP-03 | H10: ON | I10: Team: parsing, embeddings, index row
A11: CL-08 | B11: Refresh and sync | C11: L1 | D11: Recurring | E11: S | F11: E | G11: none | H11: ON | I11: Team: parsing, embeddings, index row (change rate)
A12: CL-09 | B12: Platform or gateway, build or buy | C12: L2 | D12: One-time plus recurring | E12: H | F12: E | G12: ENV-01 (B*) | H12: ON | I12: Hub: platform one-time and run
A13: CL-10 | B13: Workflow and application integration | C13: L2 | D13: One-time | E13: S | F13: E | G13: none (G11) | H13: ON | I13: Team: one-time integrate, evaluation harness
A14: CL-11 | B14: Security, privacy and legal review | C14: L2 | D14: One-time, and on material change | E14: H | F14: E | G14: none (G11) | H14: ON | I14: Hub: review one-time
... A16: CL-13 | B16: Red-teaming and adversarial testing | C16: L2 | D16: One-time, then periodic | E16: H | F16: E | G16: none (G11) | H16: ON | I16: Hub: red-team one-time and repeat
A17: CL-14 | B17: Environments and base cloud infrastructure | C17: L2 | D17: Recurring fixed | E17: H | F17: E | G17: none | H17: =IF(Params!$E$20=0,"OFF","ON") -> OFF | I17: Hub: environments
A18: CL-15 | B18: Committed capacity (provisioned cloud or self-hosted GPUs) | C18: L2 | D18: Recurring fixed | E18: H or S | F18: E | G18: BUY-05, CST-09 (C) | H18: =IF(SUM(Teams!$C$16:$G$16)=0,"OFF","ON") -> OFF | I18: Team: committed capacity row
A19: CL-16 | B19: Model tokens | C19: L3 | D19: Variable | E19: S | F19: P | G19: PRC-01 to PRC-04 | H19: ON | I19: Team: model tokens row
A20: CL-17 | B20: Retries, failed calls, agent steps | C20: L3 | D20: Variable | E20: S | F20: E | G20: none (G8) | H20: ON | I20: Multiplier inside the model tokens row
A21: CL-18 | B21: Tool and retrieval calls | C21: L3 | D21: Variable | E21: S | F21: P | G21: COMP-03, COMP-04 | H21: ON | I21: Team: tool and guardrail row
A22: CL-19 | B22: Guardrails and moderation | C22: L3 | D22: Variable | E22: H+S | F22: P | G22: COMP-05, COMP-02 | H22: ON | I22: Team: tool and guardrail row
A23: CL-20 | B23: Voice and image | C23: L3 | D23: Variable | E23: S | F23: P | G23: COMP-04 | H23: n/a (not used in this example) | I23: Not used in the worked example
A24: CL-21 | B24: Seats | C24: L3 | D24: Recurring fixed | E24: S | F24: P | G24: BUY-02, BUY-03 | H24: ON | I24: Team: seats row
A25: CL-22 | B25: Credits and outcomes | C25: L3 | D25: Variable | E25: S | F25: P | G25: BUY-04, BUY-06 | H25: ON | I25: Team: vendor per-outcome row
A26: CL-23 | B26: Residency and regional premium | C26: L3 | D26: Multiplier | E26: S | F26: P | G26: PRC-01, PRC-02, BUY-05 | H26: ON | I26: Residency multiplier inside the model tokens row
A27: CL-24 | B27: Monitoring and observability | C27: L4 | D27: Recurring fixed plus variable | E27: H | F27: P | G27: COMP-06 | H27: ON | I27: Hub: monitoring
A28: CL-25 | B28: Ongoing evaluation and quality review | C28: L4 | D28: Recurring | E28: H+S | F28: E | G28: none | H28: ON | I28: Team: quality review, maintenance, support row
A29: CL-26 | B29: Model migration events | C29: L4 | D29: Recurring event | E29: S | F29: R | G29: PRC-06 (cadence, one provider) | H29: ON | I29: Team: migration row
A30: CL-27 | B30: Prompt and workflow maintenance | C30: L4 | D30: Recurring | E30: S | F30: E | G30: none | H30: ON | I30: Team: quality review, maintenance, support row
... A33: CL-30 | B33: Cost governance (FinOps) | C33: L4 | D33: Recurring fixed | E33: H | F33: R | G33: ORG-07 (B) | H33: ON | I33: Hub: cost governance
A34: CL-31 | B34: Compliance audit and governance | C34: L4 | D34: Recurring | E34: H | F34: E | G34: none (G7) | H34: =IF(Params!$E$32=0,"OFF","ON") -> OFF | I34: Hub: compliance audit
A35: CL-32 | B35: Platform and vendor licences | C35: L4 | D35: Recurring fixed | E35: H | F35: E | G35: none | H35: =IF(Params!$E$33=0,"OFF","ON") -> OFF | I35: Hub: licences
A36: CL-33 | B36: Training and enablement | C36: L5 | D36: One-time, plus new joiners | E36: S | F36: E | G36: none | H36: ON | I36: Team: one-time training
A37: CL-34 | B37: Human review of output | C37: L5 | D37: Variable | E37: S | F37: R | G37: ORG-06 (B*), LAB-01 | H37: ON | I37: Team: human review row
A38: CL-35 | B38: Change management and champions | C38: L5 | D38: Recurring | E38: H+S | F38: E | G38: none | H38: ON | I38: Team: change champions row
A40: Tally by policy
A41: P | B41: =COUNTIF($F$4:$F$38,A41) -> 11
A42: R | B42: =COUNTIF($F$4:$F$38,A42) -> 3
A43: E | B43: =COUNTIF($F$4:$F$38,A43) -> 21
A44: Lines with no starter value are OFF and understate cost until the enterprise enters a value (CL-14, CL-15, CL-31, CL-32).

Sheet Levers
A1: Levers in their fixed order (Base scenario)
A2: Order: context and scenario scale, routing, caching, batch, residency. Below: two hand-calculated fixtures used by acceptance test 5.
A3: Step | B3: =Teams!$C$4 -> Corporate knowledge assistant (conservative calibration) | C3: =Teams!$D$4 -> Engineering assistant | D3: =Teams!$E$4 -> Customer service agent | E3: =Teams!$F$4 -> Regulated document review | F3: =Teams!$G$4 -> Sales assistant (published-range calibration)
A4: Input tokens per outcome (entered) | B4: =Teams!$C$29 -> 2000 | C4: =Teams!$D$29 -> 8000 | D4: =Teams!$E$29 -> 0 | E4: =Teams!$F$29 -> 30000 | F4: =Teams!$G$29 -> 2000
A5: Output tokens per outcome (entered) | B5: =Teams!$C$30 -> 500 | C5: =Teams!$D$30 -> 2000 | D5: =Teams!$E$30 -> 0 | E5: =Teams!$F$30 -> 1500 | F5: =Teams!$G$30 -> 500
A6: Scale: (1 - context) x scenario x retries x steps | B6: =(1-Teams!$C$31)*Params!$E$39*Params!$E$21*IF(Teams!$C$36="Yes",Params!$E$22,1) -> 1.15 | C6: =(1-Teams!$D$31)*Params!$E$39*Params!$E$21*IF(Teams!$D$36="Yes",Params!$E$22,1) -> 6.21 | D6: =(1-Teams!$E$31)*Params!$E$39*Params!$E$21*IF(Teams!$E$36="Yes",Params!$E$22,1) -> 1.15 | E6: =(1-Teams!$F$31)*Params!$E$39*Params!$E$21*IF(Teams!$F$36="Yes",Params!$E$22,1) -> 1.15 | F6: =(1-Teams!$G$31)*Params!$E$39*Params!$E$21*IF(Teams!$G$36="Yes",Params!$E$22,1) -> 1.15
A7: Input tokens after scale | B7: =B4*B6 -> 2300 | C7: =C4*C6 -> 49680 | D7: =D4*D6 -> 0 | E7: =E4*E6 -> 34500 | F7: =F4*F6 -> 2300
A8: Output tokens after scale | B8: =B5*B6 -> 575 | C8: =C5*C6 -> 12420 | D8: =D5*D6 -> 0 | E8: =E5*E6 -> 1725 | F8: =F5*F6 -> 575
A9: Blended input price after routing (USD per million) | B9: =Teams!$C$68 -> 2 | C9: =Teams!$D$68 -> 2 | D9: =Teams!$E$68 -> 2 | E9: =Teams!$F$68 -> 3.5 | F9: =Teams!$G$68 -> 2
A10: Blended output price after routing (USD per million) | B10: =Teams!$C$69 -> 10 | C10: =Teams!$D$69 -> 10 | D10: =Teams!$E$69 -> 10 | E10: =Teams!$F$69 -> 17.5 | F10: =Teams!$G$69 -> 10
A11: Input price factor after caching | B11: =Teams!$C$70 -> 0.7425 | C11: =Teams!$D$70 -> 0.4725 | D11: =Teams!$E$70 -> 1 | E11: =Teams!$F$70 -> 0.7425 | F11: =Teams!$G$70 -> 0.7425
A12: Price factor after batch share | B12: =Teams!$C$71 -> 1 | C12: =Teams!$D$71 -> 1 | D12: =Teams!$E$71 -> 1 | E12: =Teams!$F$71 -> 0.8 | F12: =Teams!$G$71 -> 1
A13: Residency multiplier | B13: =Teams!$C$35 -> 1 | C13: =Teams!$D$35 -> 1 | D13: =Teams!$E$35 -> 1 | E13: =Teams!$F$35 -> 1.1 | F13: =Teams!$G$35 -> 1
A14: Token cost per outcome (this sheet) | B14: =(B7*B9*B11+B8*B10)/1000000*B12*B13 -> 0.0091655 | C14: =(C7*C9*C11+C8*C10)/1000000*C12*C13 -> 0.1711476 | D14: =(D7*D9*D11+D8*D10)/1000000*D12*D13 -> 0 | E14: =(E7*E9*E11+E8*E10)/1000000*E12*E13 -> 0.10546305 | F14: =(F7*F9*F11+F8*F10)/1000000*F12*F13 -> 0.0091655
A15: Token cost per outcome (Calc_Base) | B15: =Calc_Base!$C$8 -> 0.0091655 | C15: =Calc_Base!$C$35 -> 0.1711476 | D15: =Calc_Base!$C$62 -> 0 | E15: =Calc_Base!$C$89 -> 0.10546305 | F15: =Calc_Base!$C$116 -> 0.0091655
A16: Difference | B16: =B14-B15 -> 0 | C16: =C14-C15 -> 0 | D16: =D14-D15 -> 0 | E16: =E14-E15 -> 0 | F16: =F14-F15 -> 0
A19: Fixtures (typed inputs; expected values hand-calculated, see build/build_out_c.py) | B19: Fixture 1 | C19: Fixture 2 | D19: Fixture 3 (provider example, no cache) | E19: Fixture 4 (provider example, 80% cached)
A20: Input tokens per outcome | B20: 10000 | C20: 20000 | D20: 50000 | E20: 50000
A21: Output tokens per outcome | B21: 1000 | C21: 2000 | D21: 15000 | E21: 15000
A22: Context-management reduction | B22: 0 | C22: 0.2 | D22: 0 | E22: 0
A23: Tokens scenario multiplier | B23: 1 | C23: 1 | D23: 1 | E23: 1
A24: Retry multiplier | B24: 1 | C24: 1.2 | D24: 1 | E24: 1
A25: Agent steps | B25: 1 | C25: 2 | D25: 1 | E25: 1
A26: Main model input price | B26: 2 | C26: 5 | D26: 5 | E26: 5
A27: Main model output price | B27: 10 | C27: 25 | D27: 25 | E27: 25
A28: Cheaper model input price | B28: 1 | C28: 1 | D28: 1 | E28: 1
A29: Cheaper model output price | B29: 5 | C29: 5 | D29: 5 | E29: 5
A30: Share routed to cheaper model | B30: 0 | C30: 0.5 | D30: 0 | E30: 0
A31: Cached share of input | B31: 0.5 | C31: 0.4 | D31: 0 | E31: 0.8
... A37: Residency multiplier | B37: 1 | C37: 1.1 | D37: 1 | E37: 1
A38: Computed cost per outcome | B38: =(B20*((1-B22)*B23*B24*B25)*((1-B30)*B26+B30*B28)*((1-B31-B32)+B31*B33+B32*B34)+B21*((1-B22)*B23*B24*B25)*((1-B30)*B27+B30*B29))/1000000*(1-B35*(1-B36))*B37 -> 0.021 | C38: =(C20*((1-C22)*C23*C24*C25)*((1-C30)*C26+C30*C28)*((1-C31-C32)+C31*C33+C32*C34)+C21*((1-C22)*C23*C24*C25)*((1-C30)*C27+C30*C29))/1000000*(1-C35*(1-C36))*C37 -> 0.12548448 | D38: =(D20*((1-D22)*D23*D24*D25)*((1-D30)*D26+D30*D28)*((1-D31-D32)+D31*D33+D32*D34)+D21*((1-D22)*D23*D24*D25)*((1-D30)*D27+D30*D29))/1000000*(1-D35*(1-D36))*D37 -> 0.625 | E38: =(E20*((1-E22)*E23*E24*E25)*((1-E30)*E26+E30*E28)*((1-E31-E32)+E31*E33+E32*E34)+E21*((1-E22)*E23*E24*E25)*((1-E30)*E27+E30*E29))/1000000*(1-E35*(1-E36))*E37 -> 0.445
A39: Expected (fixtures 1 and 2 hand-calculated; 3 and 4 from the provider's published example) | B39: 0.021 | C39: 0.12548448 | D39: 0.625 | E39: 0.445
A40: Difference | B40: =B38-B39 -> 0 | C40: =C38-C39 -> 0 | D40: =D38-D39 -> 0 | E40: =E38-E39 -> 0
A42: Fixtures 3 and 4 reproduce the worked example on Anthropic's pricing page (evidence S09, read 2026-09-20): Opus 5, 50,000 input and 15,000 output tokens. The page's totals, $0.705 without caching and $0.525 with 40,000 tokens read from cache, include $0.08 of session runtime, which is not a token cost.

Sheet Results
A1: Results for the selected scenario
A2: Every cell picks the Low-cost, Base or High-cost Calc sheet using the scenario chosen on Org.
A3: Shape factor on raw hub cost | D3: =CHOOSE(Org!$B$16,Calc_Low!$B$170,Calc_Base!$B$170,Calc_High!$B$170) -> 1
A4: Cost group | B4: Evidence | C4: Layer | D4: =Teams!C$4 -> Corporate knowledge assistant (conservative calibration) | E4: =Teams!D$4 -> Engineering assistant | F4: =Teams!E$4 -> Customer service agent | G4: =Teams!F$4 -> Regulated document review | H4: =Teams!G$4 -> Sales assistant (published-range calibration) | I4: Hub (raw) | J4: Enterprise
A5: Seats (CL-21) | B5: A | C5: 3 | D5: =CHOOSE(Org!$B$16,Calc_Low!$C$13,Calc_Base!$C$13,Calc_High!$C$13) -> 3024000 | E5: =CHOOSE(Org!$B$16,Calc_Low!$C$40,Calc_Base!$C$40,Calc_High!$C$40) -> 288000 | F5: =CHOOSE(Org!$B$16,Calc_Low!$C$67,Calc_Base!$C$67,Calc_High!$C$67) -> 0 | G5: =CHOOSE(Org!$B$16,Calc_Low!$C$94,Calc_Base!$C$94,Calc_High!$C$94) -> 0 | H5: =CHOOSE(Org!$B$16,Calc_Low!$C$121,Calc_Base!$C$121,Calc_High!$C$121) -> 2016000 | J5: =SUM(D5:H5) -> 5328000
A6: Model tokens incl. retries and agent steps (CL-16, CL-17) | B6: A | C6: 3 | D6: =CHOOSE(Org!$B$16,Calc_Low!$C$14,Calc_Base!$C$14,Calc_High!$C$14) -> 0 | E6: =CHOOSE(Org!$B$16,Calc_Low!$C$41,Calc_Base!$C$41,Calc_High!$C$41) -> 755787.8 | F6: =CHOOSE(Org!$B$16,Calc_Low!$C$68,Calc_Base!$C$68,Calc_High!$C$68) -> 0 | G6: =CHOOSE(Org!$B$16,Calc_Low!$C$95,Calc_Base!$C$95,Calc_High!$C$95) -> 42522.702 | H6: =CHOOSE(Org!$B$16,Calc_Low!$C$122,Calc_Base!$C$122,Calc_High!$C$122) -> 0 | J6: =SUM(D6:H6) -> 798310.5
A7: Vendor per-outcome price (CL-22) | B7: A | C7: 3 | D7: =CHOOSE(Org!$B$16,Calc_Low!$C$15,Calc_Base!$C$15,Calc_High!$C$15) -> 0 | E7: =CHOOSE(Org!$B$16,Calc_Low!$C$42,Calc_Base!$C$42,Calc_High!$C$42) -> 0 | F7: =CHOOSE(Org!$B$16,Calc_Low!$C$69,Calc_Base!$C$69,Calc_High!$C$69) -> 1287000 | G7: =CHOOSE(Org!$B$16,Calc_Low!$C$96,Calc_Base!$C$96,Calc_High!$C$96) -> 0 | H7: =CHOOSE(Org!$B$16,Calc_Low!$C$123,Calc_Base!$C$123,Calc_High!$C$123) -> 0 | J7: =SUM(D7:H7) -> 1287000
A8: Tool and guardrail calls (CL-18, CL-19) | B8: A | C8: 3 | D8: =CHOOSE(Org!$B$16,Calc_Low!$C$16,Calc_Base!$C$16,Calc_High!$C$16) -> 0 | E8: =CHOOSE(Org!$B$16,Calc_Low!$C$43,Calc_Base!$C$43,Calc_High!$C$43) -> 0 | F8: =CHOOSE(Org!$B$16,Calc_Low!$C$70,Calc_Base!$C$70,Calc_High!$C$70) -> 0 | G8: =CHOOSE(Org!$B$16,Calc_Low!$C$97,Calc_Base!$C$97,Calc_High!$C$97) -> 7620.48 | H8: =CHOOSE(Org!$B$16,Calc_Low!$C$124,Calc_Base!$C$124,Calc_High!$C$124) -> 0 | J8: =SUM(D8:H8) -> 7620.48
A9: Committed capacity (CL-15) | B9: E | C9: 2 | D9: =CHOOSE(Org!$B$16,Calc_Low!$C$17,Calc_Base!$C$17,Calc_High!$C$17) -> 0 | E9: =CHOOSE(Org!$B$16,Calc_Low!$C$44,Calc_Base!$C$44,Calc_High!$C$44) -> 0 | F9: =CHOOSE(Org!$B$16,Calc_Low!$C$71,Calc_Base!$C$71,Calc_High!$C$71) -> 0 | G9: =CHOOSE(Org!$B$16,Calc_Low!$C$98,Calc_Base!$C$98,Calc_High!$C$98) -> 0 | H9: =CHOOSE(Org!$B$16,Calc_Low!$C$125,Calc_Base!$C$125,Calc_High!$C$125) -> 0 | J9: =SUM(D9:H9) -> 0
A10: Parsing, embeddings, index, retrieval (CL-05 to CL-08) | B10: A | C10: 1 | D10: =CHOOSE(Org!$B$16,Calc_Low!$C$18,Calc_Base!$C$18,Calc_High!$C$18) -> 2323.8 | E10: =CHOOSE(Org!$B$16,Calc_Low!$C$45,Calc_Base!$C$45,Calc_High!$C$45) -> 2899.56 | F10: =CHOOSE(Org!$B$16,Calc_Low!$C$72,Calc_Base!$C$72,Calc_High!$C$72) -> 0 | G10: =CHOOSE(Org!$B$16,Calc_Low!$C$99,Calc_Base!$C$99,Calc_High!$C$99) -> 29769.632 | H10: =CHOOSE(Org!$B$16,Calc_Low!$C$126,Calc_Base!$C$126,Calc_High!$C$126) -> 2081.196 | J10: =SUM(D10:H10) -> 37074.188
A11: Connector upkeep (CL-03) | B11: S | C11: 1 | D11: =CHOOSE(Org!$B$16,Calc_Low!$C$19,Calc_Base!$C$19,Calc_High!$C$19) -> 10800 | E11: =CHOOSE(Org!$B$16,Calc_Low!$C$46,Calc_Base!$C$46,Calc_High!$C$46) -> 7200 | F11: =CHOOSE(Org!$B$16,Calc_Low!$C$73,Calc_Base!$C$73,Calc_High!$C$73) -> 10500 | G11: =CHOOSE(Org!$B$16,Calc_Low!$C$100,Calc_Base!$C$100,Calc_High!$C$100) -> 13600 | H11: =CHOOSE(Org!$B$16,Calc_Low!$C$127,Calc_Base!$C$127,Calc_High!$C$127) -> 7200 | J11: =SUM(D11:H11) -> 49300
A12: Quality review, maintenance, support (CL-25, CL-27, CL-28) | B12: S | C12: 4 | D12: =CHOOSE(Org!$B$16,Calc_Low!$C$20,Calc_Base!$C$20,Calc_High!$C$20) -> 250200 | E12: =CHOOSE(Org!$B$16,Calc_Low!$C$47,Calc_Base!$C$47,Calc_High!$C$47) -> 151680 | F12: =CHOOSE(Org!$B$16,Calc_Low!$C$74,Calc_Base!$C$74,Calc_High!$C$74) -> 129315 | G12: =CHOOSE(Org!$B$16,Calc_Low!$C$101,Calc_Base!$C$101,Calc_High!$C$101) -> 129120 | H12: =CHOOSE(Org!$B$16,Calc_Low!$C$128,Calc_Base!$C$128,Calc_High!$C$128) -> 210000 | J12: =SUM(D12:H12) -> 870315
A13: Model migration events (CL-26) | B13: R | C13: 4 | D13: =CHOOSE(Org!$B$16,Calc_Low!$C$21,Calc_Base!$C$21,Calc_High!$C$21) -> 12800 | E13: =CHOOSE(Org!$B$16,Calc_Low!$C$48,Calc_Base!$C$48,Calc_High!$C$48) -> 12800 | F13: =CHOOSE(Org!$B$16,Calc_Low!$C$75,Calc_Base!$C$75,Calc_High!$C$75) -> 12800 | G13: =CHOOSE(Org!$B$16,Calc_Low!$C$102,Calc_Base!$C$102,Calc_High!$C$102) -> 12800 | H13: =CHOOSE(Org!$B$16,Calc_Low!$C$129,Calc_Base!$C$129,Calc_High!$C$129) -> 12800 | J13: =SUM(D13:H13) -> 64000
A14: Human review of output (CL-34) | B14: R | C14: 5 | D14: =CHOOSE(Org!$B$16,Calc_Low!$C$22,Calc_Base!$C$22,Calc_High!$C$22) -> 424120.05 | E14: =CHOOSE(Org!$B$16,Calc_Low!$C$49,Calc_Base!$C$49,Calc_High!$C$49) -> 2070662.4 | F14: =CHOOSE(Org!$B$16,Calc_Low!$C$76,Calc_Base!$C$76,Calc_High!$C$76) -> 304785 | G14: =CHOOSE(Org!$B$16,Calc_Low!$C$103,Calc_Base!$C$103,Calc_High!$C$103) -> 945302.4 | H14: =CHOOSE(Org!$B$16,Calc_Low!$C$130,Calc_Base!$C$130,Calc_High!$C$130) -> 282746.7 | J14: =SUM(D14:H14) -> 4027616.5
A15: Change champions (CL-35) | B15: S | C15: 5 | D15: =CHOOSE(Org!$B$16,Calc_Low!$C$23,Calc_Base!$C$23,Calc_High!$C$23) -> 264000 | E15: =CHOOSE(Org!$B$16,Calc_Low!$C$50,Calc_Base!$C$50,Calc_High!$C$50) -> 35200 | F15: =CHOOSE(Org!$B$16,Calc_Low!$C$77,Calc_Base!$C$77,Calc_High!$C$77) -> 5192 | G15: =CHOOSE(Org!$B$16,Calc_Low!$C$104,Calc_Base!$C$104,Calc_High!$C$104) -> 12760 | H15: =CHOOSE(Org!$B$16,Calc_Low!$C$131,Calc_Base!$C$131,Calc_High!$C$131) -> 176000 | J15: =SUM(D15:H15) -> 493152
A16: One-time: assess, clean, connect (CL-01 to CL-03) | B16: S | C16: 1 | D16: =CHOOSE(Org!$B$16,Calc_Low!$C$24,Calc_Base!$C$24,Calc_High!$C$24) -> 34400 | E16: =CHOOSE(Org!$B$16,Calc_Low!$C$51,Calc_Base!$C$51,Calc_High!$C$51) -> 28800 | F16: =CHOOSE(Org!$B$16,Calc_Low!$C$78,Calc_Base!$C$78,Calc_High!$C$78) -> 32480 | G16: =CHOOSE(Org!$B$16,Calc_Low!$C$105,Calc_Base!$C$105,Calc_High!$C$105) -> 73600 | H16: =CHOOSE(Org!$B$16,Calc_Low!$C$132,Calc_Base!$C$132,Calc_High!$C$132) -> 22400 | J16: =SUM(D16:H16) -> 191680
A17: One-time: initial parse and embed (CL-05, CL-06) | B17: A | C17: 1 | D17: =CHOOSE(Org!$B$16,Calc_Low!$C$25,Calc_Base!$C$25,Calc_High!$C$25) -> 157.8 | E17: =CHOOSE(Org!$B$16,Calc_Low!$C$52,Calc_Base!$C$52,Calc_High!$C$52) -> 251 | F17: =CHOOSE(Org!$B$16,Calc_Low!$C$79,Calc_Base!$C$79,Calc_High!$C$79) -> 0 | G17: =CHOOSE(Org!$B$16,Calc_Low!$C$106,Calc_Base!$C$106,Calc_High!$C$106) -> 24156 | H17: =CHOOSE(Org!$B$16,Calc_Low!$C$133,Calc_Base!$C$133,Calc_High!$C$133) -> 78.9 | J17: =SUM(D17:H17) -> 24643.7
A18: One-time: integrate, evaluation harness (CL-10, CL-12) | B18: S | C18: 2 | D18: =CHOOSE(Org!$B$16,Calc_Low!$C$26,Calc_Base!$C$26,Calc_High!$C$26) -> 48000 | E18: =CHOOSE(Org!$B$16,Calc_Low!$C$53,Calc_Base!$C$53,Calc_High!$C$53) -> 48000 | F18: =CHOOSE(Org!$B$16,Calc_Low!$C$80,Calc_Base!$C$80,Calc_High!$C$80) -> 48000 | G18: =CHOOSE(Org!$B$16,Calc_Low!$C$107,Calc_Base!$C$107,Calc_High!$C$107) -> 48000 | H18: =CHOOSE(Org!$B$16,Calc_Low!$C$134,Calc_Base!$C$134,Calc_High!$C$134) -> 48000 | J18: =SUM(D18:H18) -> 240000
A19: One-time: training (CL-33) | B19: S | C19: 5 | D19: =CHOOSE(Org!$B$16,Calc_Low!$C$27,Calc_Base!$C$27,Calc_High!$C$27) -> 720000 | E19: =CHOOSE(Org!$B$16,Calc_Low!$C$54,Calc_Base!$C$54,Calc_High!$C$54) -> 128000 | F19: =CHOOSE(Org!$B$16,Calc_Low!$C$81,Calc_Base!$C$81,Calc_High!$C$81) -> 20400 | G19: =CHOOSE(Org!$B$16,Calc_Low!$C$108,Calc_Base!$C$108,Calc_High!$C$108) -> 42000 | H19: =CHOOSE(Org!$B$16,Calc_Low!$C$135,Calc_Base!$C$135,Calc_High!$C$135) -> 480000 | J19: =SUM(D19:H19) -> 1390400
A20: Hub: One-time: platform or gateway (CL-09) | B20: S | C20: 2 | I20: =CHOOSE(Org!$B$16,Calc_Low!$C$145,Calc_Base!$C$145,Calc_High!$C$145) -> 96000 | J20: =I20*$D$3 -> 96000
A21: Hub: One-time: permission mapping (CL-04) | B21: S | C21: 1 | I21: =CHOOSE(Org!$B$16,Calc_Low!$C$146,Calc_Base!$C$146,Calc_High!$C$146) -> 44800 | J21: =I21*$D$3 -> 44800
A22: Hub: One-time: security, privacy, legal review (CL-11) | B22: S | C22: 2 | I22: =CHOOSE(Org!$B$16,Calc_Low!$C$147,Calc_Base!$C$147,Calc_High!$C$147) -> 64000 | J22: =I22*$D$3 -> 64000
A23: Hub: One-time: red-teaming (CL-13) | B23: S | C23: 2 | I23: =CHOOSE(Org!$B$16,Calc_Low!$C$148,Calc_Base!$C$148,Calc_High!$C$148) -> 32000 | J23: =I23*$D$3 -> 32000
A24: Hub: Platform run (CL-09) | B24: S | C24: 2 | I24: =CHOOSE(Org!$B$16,Calc_Low!$C$149,Calc_Base!$C$149,Calc_High!$C$149) -> 57600 | J24: =I24*$D$3 -> 57600
A25: Hub: Permission upkeep (CL-04) | B25: S | C25: 1 | I25: =CHOOSE(Org!$B$16,Calc_Low!$C$150,Calc_Base!$C$150,Calc_High!$C$150) -> 13440 | J25: =I25*$D$3 -> 13440
A26: Hub: Red-team repeat (CL-13) | B26: S | C26: 2 | I26: =CHOOSE(Org!$B$16,Calc_Low!$C$151,Calc_Base!$C$151,Calc_High!$C$151) -> 48000 | J26: =I26*$D$3 -> 48000
A27: Hub: Environments (CL-14) | B27: E | C27: 2 | I27: =CHOOSE(Org!$B$16,Calc_Low!$C$152,Calc_Base!$C$152,Calc_High!$C$152) -> 0 | J27: =I27*$D$3 -> 0
A28: Hub: Monitoring and observability (CL-24) | B28: A | C28: 4 | I28: =CHOOSE(Org!$B$16,Calc_Low!$C$153,Calc_Base!$C$153,Calc_High!$C$153) -> 11735.68 | J28: =I28*$D$3 -> 11735.68
A29: Hub: Platform team (CL-29) | B29: S | C29: 4 | I29: =CHOOSE(Org!$B$16,Calc_Low!$C$154,Calc_Base!$C$154,Calc_High!$C$154) -> 2640000 | J29: =I29*$D$3 -> 2640000
A30: Hub: Cost governance (CL-30) | B30: R | C30: 4 | I30: =CHOOSE(Org!$B$16,Calc_Low!$C$155,Calc_Base!$C$155,Calc_High!$C$155) -> 528000 | J30: =I30*$D$3 -> 528000
A31: Hub: Compliance audit (CL-31) | B31: E | C31: 4 | I31: =CHOOSE(Org!$B$16,Calc_Low!$C$156,Calc_Base!$C$156,Calc_High!$C$156) -> 0 | J31: =I31*$D$3 -> 0
A32: Hub: Platform and vendor licences (CL-32) | B32: E | C32: 4 | I32: =CHOOSE(Org!$B$16,Calc_Low!$C$157,Calc_Base!$C$157,Calc_High!$C$157) -> 0 | J32: =I32*$D$3 -> 0
A33: Total cost over the horizon | D33: =SUM(D5:D32) -> 4790801.6 | E33: =SUM(E5:E32) -> 3529280.8 | F33: =SUM(F5:F32) -> 1850472 | G33: =SUM(G5:G32) -> 1381251.2 | H33: =SUM(H5:H32) -> 3257306.8 | I33: =SUM(I5:I32) -> 3535575.7 | J33: =SUM(J5:J32) -> 18344688
A35: By layer
A36: L1 Data readiness | D36: =SUMIF($C$5:$C$32,1,D$5:D$32) -> 47681.6 | E36: =SUMIF($C$5:$C$32,1,E$5:E$32) -> 39150.56 | F36: =SUMIF($C$5:$C$32,1,F$5:F$32) -> 42980 | G36: =SUMIF($C$5:$C$32,1,G$5:G$32) -> 141125.63 | H36: =SUMIF($C$5:$C$32,1,H$5:H$32) -> 31760.096 | I36: =SUMIF($C$5:$C$32,1,I$5:I$32) -> 58240 | J36: =SUMIF($C$5:$C$32,1,J$5:J$32) -> 360937.89
A37: L2 Setup and infrastructure | D37: =SUMIF($C$5:$C$32,2,D$5:D$32) -> 48000 | E37: =SUMIF($C$5:$C$32,2,E$5:E$32) -> 48000 | F37: =SUMIF($C$5:$C$32,2,F$5:F$32) -> 48000 | G37: =SUMIF($C$5:$C$32,2,G$5:G$32) -> 48000 | H37: =SUMIF($C$5:$C$32,2,H$5:H$32) -> 48000 | I37: =SUMIF($C$5:$C$32,2,I$5:I$32) -> 297600 | J37: =SUMIF($C$5:$C$32,2,J$5:J$32) -> 537600
A38: L3 Inference and usage | D38: =SUMIF($C$5:$C$32,3,D$5:D$32) -> 3024000 | E38: =SUMIF($C$5:$C$32,3,E$5:E$32) -> 1043787.8 | F38: =SUMIF($C$5:$C$32,3,F$5:F$32) -> 1287000 | G38: =SUMIF($C$5:$C$32,3,G$5:G$32) -> 50143.182 | H38: =SUMIF($C$5:$C$32,3,H$5:H$32) -> 2016000 | I38: =SUMIF($C$5:$C$32,3,I$5:I$32) -> 0 | J38: =SUMIF($C$5:$C$32,3,J$5:J$32) -> 7420931
A39: L4 Run and maintenance | D39: =SUMIF($C$5:$C$32,4,D$5:D$32) -> 263000 | E39: =SUMIF($C$5:$C$32,4,E$5:E$32) -> 164480 | F39: =SUMIF($C$5:$C$32,4,F$5:F$32) -> 142115 | G39: =SUMIF($C$5:$C$32,4,G$5:G$32) -> 141920 | H39: =SUMIF($C$5:$C$32,4,H$5:H$32) -> 222800 | I39: =SUMIF($C$5:$C$32,4,I$5:I$32) -> 3179735.7 | J39: =SUMIF($C$5:$C$32,4,J$5:J$32) -> 4114050.7
A40: L5 People and change | D40: =SUMIF($C$5:$C$32,5,D$5:D$32) -> 1408120 | E40: =SUMIF($C$5:$C$32,5,E$5:E$32) -> 2233862.4 | F40: =SUMIF($C$5:$C$32,5,F$5:F$32) -> 330377 | G40: =SUMIF($C$5:$C$32,5,G$5:G$32) -> 1000062.4 | H40: =SUMIF($C$5:$C$32,5,H$5:H$32) -> 938746.7 | I40: =SUMIF($C$5:$C$32,5,I$5:I$32) -> 0 | J40: =SUMIF($C$5:$C$32,5,J$5:J$32) -> 5911168.5
A42: By evidence category | D42: Cost | E42: Share
...

Sheet Scenarios
A1: Scenarios side by side
A2: Low-cost, Base and High-cost, each from its own Calc sheet. Value case follows the Org selection.
A3: Enterprise, over the horizon | B3: Low-cost | C3: Base | D3: High-cost (stress case) | E3: Low <= Base <= High
A4: L1 Data readiness | B4: =Calc_Low!$C$18+Calc_Low!$C$19+Calc_Low!$C$24+Calc_Low!$C$25+Calc_Low!$C$45+Calc_Low!$C$46+Calc_Low!$C$51+Calc_Low!$C$52+Calc_Low!$C$72+Calc_Low!$C$73+Calc_Low!$C$78+Calc_Low!$C$79+Calc_Low!$C$99+Calc_Low!$C$100+Calc_Low!$C$105+Calc_Low!$C$106+Calc_Low!$C$126+Calc_Low!$C$127+Calc_Low!$C$132+Calc_Low!$C$133+Calc_Low!$B$170*(Calc_Low!$C$146+Calc_Low!$C$150) -> 165854 | C4: =Calc_Base!$C$18+Calc_Base!$C$19+Calc_Base!$C$24+Calc_Base!$C$25+Calc_Base!$C$45+Calc_Base!$C$46+Calc_Base!$C$51+Calc_Base!$C$52+Calc_Base!$C$72+Calc_Base!$C$73+Calc_Base!$C$78+Calc_Base!$C$79+Calc_Base!$C$99+Calc_Base!$C$100+Calc_Base!$C$105+Calc_Base!$C$106+Calc_Base!$C$126+Calc_Base!$C$127+Calc_Base!$C$132+Calc_Base!$C$133+Calc_Base!$B$170*(Calc_Base!$C$146+Calc_Base!$C$150) -> 360937.89 | D4: =Calc_High!$C$18+Calc_High!$C$19+Calc_High!$C$24+Calc_High!$C$25+Calc_High!$C$45+Calc_High!$C$46+Calc_High!$C$51+Calc_High!$C$52+Calc_High!$C$72+Calc_High!$C$73+Calc_High!$C$78+Calc_High!$C$79+Calc_High!$C$99+Calc_High!$C$100+Calc_High!$C$105+Calc_High!$C$106+Calc_High!$C$126+Calc_High!$C$127+Calc_High!$C$132+Calc_High!$C$133+Calc_High!$B$170*(Calc_High!$C$146+Calc_High!$C$150) -> 1012894.8 | E4: =IF(AND(B4<=C4,C4<=D4),"OK","CHECK") -> OK
A5: L2 Setup and infrastructure | B5: =Calc_Low!$C$17+Calc_Low!$C$26+Calc_Low!$C$44+Calc_Low!$C$53+Calc_Low!$C$71+Calc_Low!$C$80+Calc_Low!$C$98+Calc_Low!$C$107+Calc_Low!$C$125+Calc_Low!$C$134+Calc_Low!$B$170*(Calc_Low!$C$145+Calc_Low!$C$147+Calc_Low!$C$148+Calc_Low!$C$149+Calc_Low!$C$151+Calc_Low!$C$152) -> 207400 | C5: =Calc_Base!$C$17+Calc_Base!$C$26+Calc_Base!$C$44+Calc_Base!$C$53+Calc_Base!$C$71+Calc_Base!$C$80+Calc_Base!$C$98+Calc_Base!$C$107+Calc_Base!$C$125+Calc_Base!$C$134+Calc_Base!$B$170*(Calc_Base!$C$145+Calc_Base!$C$147+Calc_Base!$C$148+Calc_Base!$C$149+Calc_Base!$C$151+Calc_Base!$C$152) -> 537600 | D5: =Calc_High!$C$17+Calc_High!$C$26+Calc_High!$C$44+Calc_High!$C$53+Calc_High!$C$71+Calc_High!$C$80+Calc_High!$C$98+Calc_High!$C$107+Calc_High!$C$125+Calc_High!$C$134+Calc_High!$B$170*(Calc_High!$C$145+Calc_High!$C$147+Calc_High!$C$148+Calc_High!$C$149+Calc_High!$C$151+Calc_High!$C$152) -> 1744000 | E5: =IF(AND(B5<=C5,C5<=D5),"OK","CHECK") -> OK
A6: L3 Inference and usage | B6: =Calc_Low!$C$13+Calc_Low!$C$14+Calc_Low!$C$15+Calc_Low!$C$16+Calc_Low!$C$40+Calc_Low!$C$41+Calc_Low!$C$42+Calc_Low!$C$43+Calc_Low!$C$67+Calc_Low!$C$68+Calc_Low!$C$69+Calc_Low!$C$70+Calc_Low!$C$94+Calc_Low!$C$95+Calc_Low!$C$96+Calc_Low!$C$97+Calc_Low!$C$121+Calc_Low!$C$122+Calc_Low!$C$123+Calc_Low!$C$124 -> 6891321.5 | C6: =Calc_Base!$C$13+Calc_Base!$C$14+Calc_Base!$C$15+Calc_Base!$C$16+Calc_Base!$C$40+Calc_Base!$C$41+Calc_Base!$C$42+Calc_Base!$C$43+Calc_Base!$C$67+Calc_Base!$C$68+Calc_Base!$C$69+Calc_Base!$C$70+Calc_Base!$C$94+Calc_Base!$C$95+Calc_Base!$C$96+Calc_Base!$C$97+Calc_Base!$C$121+Calc_Base!$C$122+Calc_Base!$C$123+Calc_Base!$C$124 -> 7420931 | D6: =Calc_High!$C$13+Calc_High!$C$14+Calc_High!$C$15+Calc_High!$C$16+Calc_High!$C$40+Calc_High!$C$41+Calc_High!$C$42+Calc_High!$C$43+Calc_High!$C$67+Calc_High!$C$68+Calc_High!$C$69+Calc_High!$C$70+Calc_High!$C$94+Calc_High!$C$95+Calc_High!$C$96+Calc_High!$C$97+Calc_High!$C$121+Calc_High!$C$122+Calc_High!$C$123+Calc_High!$C$124 -> 11634868 | E6: =IF(AND(B6<=C6,C6<=D6),"OK","CHECK") -> OK
A7: L4 Run and maintenance | B7: =Calc_Low!$C$20+Calc_Low!$C$21+Calc_Low!$C$47+Calc_Low!$C$48+Calc_Low!$C$74+Calc_Low!$C$75+Calc_Low!$C$101+Calc_Low!$C$102+Calc_Low!$C$128+Calc_Low!$C$129+Calc_Low!$B$170*(Calc_Low!$C$153+Calc_Low!$C$154+Calc_Low!$C$155+Calc_Low!$C$156+Calc_Low!$C$157) -> 1980275.1 | C7: =Calc_Base!$C$20+Calc_Base!$C$21+Calc_Base!$C$47+Calc_Base!$C$48+Calc_Base!$C$74+Calc_Base!$C$75+Calc_Base!$C$101+Calc_Base!$C$102+Calc_Base!$C$128+Calc_Base!$C$129+Calc_Base!$B$170*(Calc_Base!$C$153+Calc_Base!$C$154+Calc_Base!$C$155+Calc_Base!$C$156+Calc_Base!$C$157) -> 4114050.7 | D7: =Calc_High!$C$20+Calc_High!$C$21+Calc_High!$C$47+Calc_High!$C$48+Calc_High!$C$74+Calc_High!$C$75+Calc_High!$C$101+Calc_High!$C$102+Calc_High!$C$128+Calc_High!$C$129+Calc_High!$B$170*(Calc_High!$C$153+Calc_High!$C$154+Calc_High!$C$155+Calc_High!$C$156+Calc_High!$C$157) -> 15856426 | E7: =IF(AND(B7<=C7,C7<=D7),"OK","CHECK") -> OK
A8: L5 People and change | B8: =Calc_Low!$C$22+Calc_Low!$C$23+Calc_Low!$C$27+Calc_Low!$C$49+Calc_Low!$C$50+Calc_Low!$C$54+Calc_Low!$C$76+Calc_Low!$C$77+Calc_Low!$C$81+Calc_Low!$C$103+Calc_Low!$C$104+Calc_Low!$C$108+Calc_Low!$C$130+Calc_Low!$C$131+Calc_Low!$C$135 -> 2284314.9 | C8: =Calc_Base!$C$22+Calc_Base!$C$23+Calc_Base!$C$27+Calc_Base!$C$49+Calc_Base!$C$50+Calc_Base!$C$54+Calc_Base!$C$76+Calc_Base!$C$77+Calc_Base!$C$81+Calc_Base!$C$103+Calc_Base!$C$104+Calc_Base!$C$108+Calc_Base!$C$130+Calc_Base!$C$131+Calc_Base!$C$135 -> 5911168.5 | D8: =Calc_High!$C$22+Calc_High!$C$23+Calc_High!$C$27+Calc_High!$C$49+Calc_High!$C$50+Calc_High!$C$54+Calc_High!$C$76+Calc_High!$C$77+Calc_High!$C$81+Calc_High!$C$103+Calc_High!$C$104+Calc_High!$C$108+Calc_High!$C$130+Calc_High!$C$131+Calc_High!$C$135 -> 19377365 | E8: =IF(AND(B8<=C8,C8<=D8),"OK","CHECK") -> OK
A9: Total cost | B9: =SUM(B4:B8) -> 11529165 | C9: =SUM(C4:C8) -> 18344688 | D9: =SUM(D4:D8) -> 49625554 | E9: =IF(AND(B9<=C9,C9<=D9),"OK","CHECK") -> OK
A10: Benefit | B10: =Calc_Low!$C$174 -> 26033657 | C10: =Calc_Base!$C$174 -> 26033657 | D10: =Calc_High!$C$174 -> 26033657
A11: Net value | B11: =B10-B9 -> 14504491 | C11: =C10-C9 -> 7688968.4 | D11: =D10-D9 -> -23591897
A12: Payback month | B12: =Calc_Low!$C$179 -> 6 | C12: =Calc_Base!$C$179 -> 12 | D12: =Calc_High!$C$179 -> None
A13: Cost per outcome | B13: =IF((Calc_Low!$C$12+Calc_Low!$C$39+Calc_Low!$C$66+Calc_Low!$C$93+Calc_Low!$C$120)=0,0,B9/(Calc_Low!$C$12+Calc_Low!$C$39+Calc_Low!$C$66+Calc_Low!$C$93+Calc_Low!$C$120)) -> 0.94896499 | C13: =IF((Calc_Base!$C$12+Calc_Base!$C$39+Calc_Base!$C$66+Calc_Base!$C$93+Calc_Base!$C$120)=0,0,C9/(Calc_Base!$C$12+Calc_Base!$C$39+Calc_Base!$C$66+Calc_Base!$C$93+Calc_Base!$C$120)) -> 1.5099503 | D13: =IF((Calc_High!$C$12+Calc_High!$C$39+Calc_High!$C$66+Calc_High!$C$93+Calc_High!$C$120)=0,0,D9/(Calc_High!$C$12+Calc_High!$C$39+Calc_High!$C$66+Calc_High!$C$93+Calc_High!$C$120)) -> 4.0846767
A15: High-cost is a stress case: every parameter at its high value at once. It is not a likely outcome. Published forecast-miss rates (FCS-01, grade C) are much narrower.

Sheet Sensitivity
A1: Sensitivity and the kill number
A2: One-at-a-time, linear scaling of the selected scenario's components. Checked in Phase 5 by full recalculation: exact for realisation, minutes saved, acceptance, tokens, review minutes and effort; approximate for adoption and volume (about 8% of that driver's swing at x0.7). Multipliers are grade D inputs.
A4: Benefit (B) | B4: =Results!$J$54 -> 26033657
A5: Total cost | B5: =Results!$J$57 -> 18344688
A6: Net value (N0 = B minus cost) | B6: =B4-B5 -> 7688968.4
A7: Model token cost | B7: =SUM(Results!D6:H6) -> 798310.5
A8: Human review cost | B8: =SUM(Results!D14:H14) -> 4027616.5
A9: Volume-driven cost (tokens, vendor, tools, review) | B9: =SUM(Results!D6:H6)+SUM(Results!D7:H7)+SUM(Results!D8:H8)+SUM(Results!D14:H14) -> 6120547.5
A10: Person-day-rate-driven effort cost (starter effort lines, migration, cost governance; hub after shape) | B10: =Results!D45+SUM(Results!D13:H13)+Results!J30 -> 6822687
A12: Driver | B12: Effect on net value per +100% (USD) | C12: Low multiplier | D12: High multiplier | E12: Net value at low | F12: Net value at high | G12: Swing | H12: Rank | I12: Break-even multiplier | J12: Margin of safety | K12: Direction | L12: Break-even value (where a single scalar exists)
A13: Realisation share of self-reported time saved | B13: =$B$4 -> 26033657 | C13: 0.5 | D13: 1.5 | E13: =$B$6+(C13-1)*B13 -> -5327859.8 | F13: =$B$6+(D13-1)*B13 -> 20705797 | G13: =ABS(F13-E13) -> 26033657 | H13: =RANK(G13,$G$13:$G$19)+COUNTIF($G$13:G13,G13)-1 -> 1 | I13: =IF(B13=0,"n/a",1-$B$6/B13) -> 0.70465277 | J13: =IF(B13=0,1000000000,$B$6/ABS(B13)) -> 0.29534723 | K13: =IF(B13>0,"can fall by","can rise by") -> can fall by | L13: =I13*INDEX(Params!$D$41:$F$41,Org!$B$17) -> 0.35232638
A14: Minutes saved per outcome | B14: =$B$4 -> 26033657 | C14: 0.5 | D14: 1.5 | E14: =$B$6+(C14-1)*B14 -> -5327859.8 | F14: =$B$6+(D14-1)*B14 -> 20705797 | G14: =ABS(F14-E14) -> 26033657 | H14: =RANK(G14,$G$13:$G$19)+COUNTIF($G$13:G14,G14)-1 -> 2 | I14: =IF(B14=0,"n/a",1-$B$6/B14) -> 0.70465277 | J14: =IF(B14=0,1000000000,$B$6/ABS(B14)) -> 0.29534723 | K14: =IF(B14>0,"can fall by","can rise by") -> can fall by
A15: Quality or acceptance rate | B15: =$B$4 -> 26033657 | C15: 0.8 | D15: 1.1 | E15: =$B$6+(C15-1)*B15 -> 2482237.1 | F15: =$B$6+(D15-1)*B15 -> 10292334 | G15: =ABS(F15-E15) -> 7810097 | H15: =RANK(G15,$G$13:$G$19)+COUNTIF($G$13:G15,G15)-1 -> 5 | I15: =IF(B15=0,"n/a",1-$B$6/B15) -> 0.70465277 | J15: =IF(B15=0,1000000000,$B$6/ABS(B15)) -> 0.29534723 | K15: =IF(B15>0,"can fall by","can rise by") -> can fall by
A16: Adoption and volume (active share, outcomes) | B16: =$B$4-$B$9 -> 19913109 | C16: 0.7 | D16: 1.3 | E16: =$B$6+(C16-1)*B16 -> 1715035.7 | F16: =$B$6+(D16-1)*B16 -> 13662901 | G16: =ABS(F16-E16) -> 11947865 | H16: =RANK(G16,$G$13:$G$19)+COUNTIF($G$13:G16,G16)-1 -> 3 | I16: =IF(B16=0,"n/a",1-$B$6/B16) -> 0.61387403 | J16: =IF(B16=0,1000000000,$B$6/ABS(B16)) -> 0.38612597 | K16: =IF(B16>0,"can fall by","can rise by") -> can fall by
